Workbook
Name \A: #REF!
Name \A: #REF!
Name \E: #REF!
Name \E: #REF!
Name \L: #REF!
Name \L: #REF!
Name \S: #REF!
Name \S: #REF!
Name __cii2: [1]CII!$C$3:$Q$316
Name __dov01: '[2]tsy summary'!$U$151
Name __dur10: '[3]Treasury Yields'!$H$14
Name __dur2: '[2]tsy summary'!$H$20
Name __dur3: '[2]tsy summary'!$H$21
Name __dur4: '[2]tsy summary'!$H$23
Name __dur5: '[2]tsy summary'!$H$26
Name __Num10: '[4]Maturing Loans'!$A$1
Name __Num11: '[4]Macro-Level Slowdown'!$A$1
Name __Num12: '[4]Interest Rate Risk'!$A$1
Name __Num13: '[4]Position by State'!$A$1
Name __Num14: '[4]Position by Type'!$A$1
Name __Num15: '[4]Position by LTV'!$A$1
Name __Num16: '[4]Top Ten Commitments'!$A$1
Name __Num17: [4]Requests!$A$1
Name __Num2: '[4]Table of Contents'!$A$1
Name __Num21: '[4]Position by DSCR'!$A$1
Name __Num22: '[4]Position by DSCR'!$A$1
Name __Num5: '[4]Security History'!$A$1
Name __Num6: '[4]Risk Rating'!$A$1
Name __Num7: [4]Watchlist!$A$1
Name __Num8: [4]Delinquency!$A$1
Name __Num9: [4]Pipeline!$A$1
Name __prc10: '[3]Treasury Yields'!$G$14
Name __prc2: '[2]tsy summary'!$G$20
Name __prc3: '[2]tsy summary'!$G$21
Name __prc4: '[2]tsy summary'!$G$23
Name __prc5: '[2]tsy summary'!$G$26
Name __TSY15: '[2]tsy summary'!$C$13
Name __TSY16: '[5]tsy summary'!$C$14
Name __TSY25: '[5]tsy summary'!$C$16
Name _100_0G_A1: #REF!
Name _100_0G_A1: #REF!
Name _104_0HBG: #REF!
Name _104_0HBG: #REF!
Name _108_0INST: #REF!
Name _108_0INST: #REF!
Name _112_0TOT: #REF!
Name _112_0TOT: #REF!
Name _116_9_0FACTO: #REF!
Name _116_9_0FACTO: #REF!
Name _12_0H: #REF!
Name _12_0H: #REF!
Name _120L_0CDG: #REF!
Name _120L_0CDG: #REF!
Name _124L_0ERASE: #REF!
Name _124L_0ERASE: #REF!
Name _128Y_0CDG: #REF!
Name _128Y_0CDG: #REF!
Name _132Y_0ERASE: #REF!
Name _132Y_0ERASE: #REF!
Name _16_0CSG: #REF!

Sheet Checklist
A1: Cash Entries Signoff | B1: 202511
E3: Prepare | G3: Review
E4: Date | F4: Preparer | G4: Date | H4: Reviewer | I4: OPEN
A5: 45964 | B5: ="DC"&TEXT(A5,"mm")&TEXT(A5,"dd")&RIGHT(YEAR(A5),2)&1 -> DC1103251 | C5: ="Cash Activity "&TEXT(A5,"m")&"-"&TEXT(A5,"d") -> Cash Activity 11-3 | D5: ="Cash Entries "&TEXT(A5,"m")&"-"&TEXT(A5,"d") -> Cash Entries 11-3 | E5: 45966 | F5: AP | G5: 45966 | H5: BJJ
A6: =WORKDAY.INTL(A5,1,"0000011") -> 45965 | B6: ="DC"&TEXT(A6,"mm")&TEXT(A6,"dd")&RIGHT(YEAR(A6),2)&1 -> DC1104251 | C6: ="Cash Activity "&TEXT(A6,"m")&"-"&TEXT(A6,"d") -> Cash Activity 11-4 | D6: ="Cash Entries "&TEXT(A6,"m")&"-"&TEXT(A6,"d") -> Cash Entries 11-4 | E6: 45966 | F6: AP | G6: 45966 | H6: BJJ | I6: Incorrect advance wire – refund expected | J6: IMA Check
A7: =WORKDAY.INTL(A6,1,"0000011") -> 45966 | B7: ="DC"&TEXT(A7,"mm")&TEXT(A7,"dd")&RIGHT(YEAR(A7),2)&1 -> DC1105251 | C7: ="Cash Activity "&TEXT(A7,"m")&"-"&TEXT(A7,"d") -> Cash Activity 11-5 | D7: ="Cash Entries "&TEXT(A7,"m")&"-"&TEXT(A7,"d") -> Cash Entries 11-5 | E7: 45968 | F7: AP | G7: 45968 | H7: BJJ
A8: =WORKDAY.INTL(A7,1,"0000011") -> 45967 | B8: ="DC"&TEXT(A8,"mm")&TEXT(A8,"dd")&RIGHT(YEAR(A8),2)&1 -> DC1106251 | C8: ="Cash Activity "&TEXT(A8,"m")&"-"&TEXT(A8,"d") -> Cash Activity 11-6 | D8: ="Cash Entries "&TEXT(A8,"m")&"-"&TEXT(A8,"d") -> Cash Entries 11-6 | E8: 45968 | F8: AP | G8: 45968 | H8: BJJ | I8: Check Deposited Return - DG - Effingham IL; Unnamed remits
A9: =WORKDAY.INTL(A8,1,"0000011") -> 45968 | B9: ="DC"&TEXT(A10,"mm")&TEXT(A10,"dd")&RIGHT(YEAR(A10),2)&1 -> DC1110251 | C9: ="Cash Activity "&TEXT(A10,"m")&"-"&TEXT(A10,"d") -> Cash Activity 11-10 | D9: ="Cash Entries "&TEXT(A10,"m")&"-"&TEXT(A10,"d") -> Cash Entries 11-10 | E9: 45973 | F9: AP | G9: 45979 | H9: BJJ
A10: =WORKDAY.INTL(A9,1,"0000011") -> 45971 | B10: ="DC"&TEXT(A9,"mm")&TEXT(A9,"dd")&RIGHT(YEAR(A9),2)&1 -> DC1107251 | C10: ="Cash Activity "&TEXT(A9,"m")&"-"&TEXT(A9,"d") -> Cash Activity 11-7 | D10: ="Cash Entries "&TEXT(A9,"m")&"-"&TEXT(A9,"d") -> Cash Entries 11-7 | E10: 45973 | F10: AP | G10: 45979 | H10: BJJ
A11: 45973 | B11: ="DC"&TEXT(A11,"mm")&TEXT(A11,"dd")&RIGHT(YEAR(A11),2)&1 -> DC1112251 | C11: ="Cash Activity "&TEXT(A11,"m")&"-"&TEXT(A11,"d") -> Cash Activity 11-12 | D11: ="Cash Entries "&TEXT(A11,"m")&"-"&TEXT(A11,"d") -> Cash Entries 11-12 | E11: 45978 | F11: AP | G11: 45979 | H11: BJJ
A12: =WORKDAY.INTL(A11,1,"0000011") -> 45974 | B12: ="DC"&TEXT(A12,"mm")&TEXT(A12,"dd")&RIGHT(YEAR(A12),2)&1 -> DC1113251 | C12: ="Cash Activity "&TEXT(A12,"m")&"-"&TEXT(A12,"d") -> Cash Activity 11-13 | D12: ="Cash Entries "&TEXT(A12,"m")&"-"&TEXT(A12,"d") -> Cash Entries 11-13 | E12: 45978 | F12: AP | G12: 45979 | H12: BJJ
A13: =WORKDAY.INTL(A12,1,"0000011") -> 45975 | B13: ="DC"&TEXT(A13,"mm")&TEXT(A13,"dd")&RIGHT(YEAR(A13),2)&1 -> DC1114251 | C13: ="Cash Activity "&TEXT(A13,"m")&"-"&TEXT(A13,"d") -> Cash Activity 11-14 | D13: ="Cash Entries "&TEXT(A13,"m")&"-"&TEXT(A13,"d") -> Cash Entries 11-14 | E13: 45978 | F13: AP | G13: 45979 | H13: BJJ
A14: =WORKDAY.INTL(A13,1,"0000011") -> 45978 | B14: ="DC"&TEXT(A14,"mm")&TEXT(A14,"dd")&RIGHT(YEAR(A14),2)&1 -> DC1117251 | C14: ="Cash Activity "&TEXT(A14,"m")&"-"&TEXT(A14,"d") -> Cash Activity 11-17 | D14: ="Cash Entries "&TEXT(A14,"m")&"-"&TEXT(A14,"d") -> Cash Entries 11-17 | E14: 45979 | F14: AP | G14: 45979 | H14: BJJ
A15: =WORKDAY.INTL(A14,1,"0000011") -> 45979 | B15: ="DC"&TEXT(A15,"mm")&TEXT(A15,"dd")&RIGHT(YEAR(A15),2)&1 -> DC1118251 | C15: ="Cash Activity "&TEXT(A15,"m")&"-"&TEXT(A15,"d") -> Cash Activity 11-18 | D15: ="Cash Entries "&TEXT(A15,"m")&"-"&TEXT(A15,"d") -> Cash Entries 11-18 | E15: 45982 | F15: AP
A16: =WORKDAY.INTL(A15,1,"0000011") -> 45980 | B16: ="DC"&TEXT(A16,"mm")&TEXT(A16,"dd")&RIGHT(YEAR(A16),2)&1 -> DC1119251 | C16: ="Cash Activity "&TEXT(A16,"m")&"-"&TEXT(A16,"d") -> Cash Activity 11-19 | D16: ="Cash Entries "&TEXT(A16,"m")&"-"&TEXT(A16,"d") -> Cash Entries 11-19 | E16: 45982 | F16: AP
A17: =WORKDAY.INTL(A16,1,"0000011") -> 45981 | B17: ="DC"&TEXT(A17,"mm")&TEXT(A17,"dd")&RIGHT(YEAR(A17),2)&1 -> DC1120251 | C17: ="Cash Activity "&TEXT(A17,"m")&"-"&TEXT(A17,"d") -> Cash Activity 11-20 | D17: ="Cash Entries "&TEXT(A17,"m")&"-"&TEXT(A17,"d") -> Cash Entries 11-20 | E17: 45982 | F17: AP
A18: =WORKDAY.INTL(A17,1,"0000011") -> 45982 | B18: ="DC"&TEXT(A18,"mm")&TEXT(A18,"dd")&RIGHT(YEAR(A18),2)&1 -> DC1121251 | C18: ="Cash Activity "&TEXT(A18,"m")&"-"&TEXT(A18,"d") -> Cash Activity 11-21 | D18: ="Cash Entries "&TEXT(A18,"m")&"-"&TEXT(A18,"d") -> Cash Entries 11-21
A19: =WORKDAY.INTL(A18,1,"0000011") -> 45985 | B19: ="DC"&TEXT(A19,"mm")&TEXT(A19,"dd")&RIGHT(YEAR(A19),2)&1 -> DC1124251 | C19: ="Cash Activity "&TEXT(A19,"m")&"-"&TEXT(A19,"d") -> Cash Activity 11-24 | D19: ="Cash Entries "&TEXT(A19,"m")&"-"&TEXT(A19,"d") -> Cash Entries 11-24
A20: =WORKDAY.INTL(A19,1,"0000011") -> 45986 | B20: ="DC"&TEXT(A20,"mm")&TEXT(A20,"dd")&RIGHT(YEAR(A20),2)&1 -> DC1125251 | C20: ="Cash Activity "&TEXT(A20,"m")&"-"&TEXT(A20,"d") -> Cash Activity 11-25 | D20: ="Cash Entries "&TEXT(A20,"m")&"-"&TEXT(A20,"d") -> Cash Entries 11-25
A21: =WORKDAY.INTL(A20,1,"0000011") -> 45987 | B21: ="DC"&TEXT(A21,"mm")&TEXT(A21,"dd")&RIGHT(YEAR(A21),2)&1 -> DC1126251 | C21: ="Cash Activity "&TEXT(A21,"m")&"-"&TEXT(A21,"d") -> Cash Activity 11-26 | D21: ="Cash Entries "&TEXT(A21,"m")&"-"&TEXT(A21,"d") -> Cash Entries 11-26
A22: =WORKDAY.INTL(A21,1,"0000011") -> 45988 | B22: ="DC"&TEXT(A22,"mm")&TEXT(A22,"dd")&RIGHT(YEAR(A22),2)&1 -> DC1127251 | C22: ="Cash Activity "&TEXT(A22,"m")&"-"&TEXT(A22,"d") -> Cash Activity 11-27 | D22: ="Cash Entries "&TEXT(A22,"m")&"-"&TEXT(A22,"d") -> Cash Entries 11-27
A23: =WORKDAY.INTL(A22,1,"0000011") -> 45989 | B23: ="DC"&TEXT(A23,"mm")&TEXT(A23,"dd")&RIGHT(YEAR(A23),2)&1 -> DC1128251 | C23: ="Cash Activity "&TEXT(A23,"m")&"-"&TEXT(A23,"d") -> Cash Activity 11-28 | D23: ="Cash Entries "&TEXT(A23,"m")&"-"&TEXT(A23,"d") -> Cash Entries 11-28

Sheet Cash Activity 11-3
A1: ="Daily Bank Activity - "&MONTH(Checklist!A5)&"/"&DAY(Checklist!A5)&"/"&YEAR(Checklist!A5) -> Daily Bank Activity - 11/3/2025
A2: Credit (+) / Debit (-)
B4: # | C4: Bank | D4: Acct Name | E4: Acct # | F4: Date | G4: Type | H4: Amount | I4: Bank Ref | J4: Bank Stmt Description | K4: Trans Type | L4: Entity | M4: AIT | N4: Short Description | O4: GL Account 1 | P4: GL Account 2 | Q4: Posted?
B5: 1 | C5: PNC | D5: LCFH REIT | E5: 8026459924 | F5: 45964 | G5: CR | H5: 803.27 | I5: '00000000000 | J5: PNC SWEEP INTEREST @ 0.000000 EFFECTIVE DATE 10-31 | K5: =IF(ISNUMBER(SEARCH("Manual Payment - ",N5,1)),"AP",IF(ISNUMBER(SEARCH("Payment - Concur",N5,1)),"WDL",IF(ISNUMBER(SEARCH("Payroll Transfer",N5,1)),"XFR",IF(ISNUMBER(SEARCH("XFR",N5,1)),"XFR",IF(H5>0,"RCT","WDL"))))) -> RCT | L5: =VLOOKUP(D5,'Entity Code'!A:B,2,0) -> LCFHR | N5: Overnight interest sweep PNC LCFHR account. No entry required | O5: N/A | P5: N/A | Q5: N/A
B6: 2 | C6: PNC | D6: LCFH REIT | E6: 8026459924 | F6: 45964 | G6: CR | H6: 3102567.1 | I6: '00000000000 | J6: SWEEP TRANSFR FROM INVESTMENT ACCT 8026459924 | K6: =IF(ISNUMBER(SEARCH("Manual Payment - ",N6,1)),"AP",IF(ISNUMBER(SEARCH("Payment - Concur",N6,1)),"WDL",IF(ISNUMBER(SEARCH("Payroll Transfer",N6,1)),"XFR",IF(ISNUMBER(SEARCH("XFR",N6,1)),"XFR",IF(H6>0,"RCT","WDL"))))) -> RCT | L6: =VLOOKUP(D6,'Entity Code'!A:B,2,0) -> LCFHR | N6: Overnight interest sweep PNC LCFHR account. No entry required | O6: N/A | P6: N/A | Q6: N/A
B7: 3 | C7: PNC | D7: LCFH REIT | E7: 8026459924 | F7: 45964 | G7: DR | H7: -2452621.7 | I7: '00000000000 | J7: SWEEP TO INVESTMENT ACCT# 8026459924 | K7: =IF(ISNUMBER(SEARCH("Manual Payment - ",N7,1)),"AP",IF(ISNUMBER(SEARCH("Payment - Concur",N7,1)),"WDL",IF(ISNUMBER(SEARCH("Payroll Transfer",N7,1)),"XFR",IF(ISNUMBER(SEARCH("XFR",N7,1)),"XFR",IF(H7>0,"RCT","WDL"))))) -> WDL | L7: =VLOOKUP(D7,'Entity Code'!A:B,2,0) -> LCFHR | N7: Overnight interest sweep PNC LCFHR account. No entry required | O7: N/A | P7: N/A | Q7: N/A
B8: 4 | C8: PNC | D8: LCFH REIT | E8: 8026459924 | F8: 45964 | G8: DR | H8: -8025016.7 | I8: 'PAB3C462791H04W8 | J8: WIRE TRANSFER ISO AMT:USD 8025016.67 STTLMT DATE:1 | K8: =IF(ISNUMBER(SEARCH("Manual Payment - ",N8,1)),"AP",IF(ISNUMBER(SEARCH("Payment - Concur",N8,1)),"WDL",IF(ISNUMBER(SEARCH("Payroll Transfer",N8,1)),"XFR",IF(ISNUMBER(SEARCH("XFR",N8,1)),"XFR",IF(H8>0,"RCT","WDL"))))) -> WDL | L8: =VLOOKUP(D8,'Entity Code'!A:B,2,0) -> LCFHR | N8: SocGen Paydown | O8: 2701-CAMR-000 | P8: N/A | Q8: SS&C to post
B9: 5 | C9: PNC | D9: LCR 3 | E9: 8026496047 | F9: 45964 | G9: DR | H9: -182796.41 | I9: 'PAB3E3959A6H22KU | J9: WIRE TRANSFER ISO AMT:USD 182796.41 STTLMT DATE:11 | K9: =IF(ISNUMBER(SEARCH("Manual Payment - ",N9,1)),"AP",IF(ISNUMBER(SEARCH("Payment - Concur",N9,1)),"WDL",IF(ISNUMBER(SEARCH("Payroll Transfer",N9,1)),"XFR",IF(ISNUMBER(SEARCH("XFR",N9,1)),"XFR",IF(H9>0,"RCT","WDL"))))) -> WDL | L9: =VLOOKUP(D9,'Entity Code'!A:B,2,0) -> LCR3 | N9: Central Florida Resource Center - Future Funding Advance #1 | O9: 2701-LMS0-000 | P9: N/A | Q9: SS&C to post
B10: 6 | C10: PNC | D10: LCC | E10: 8026482868 | F10: 45964 | G10: DR | H10: -52732 | I10: 'PAB3C46274QI23NZ | J10: WIRE TRANSFER ISO AMT:USD 52732.00 STTLMT DATE:110 | K10: =IF(ISNUMBER(SEARCH("Manual Payment - ",N10,1)),"AP",IF(ISNUMBER(SEARCH("Payment - Concur",N10,1)),"WDL",IF(ISNUMBER(SEARCH("Payroll Transfer",N10,1)),"XFR",IF(ISNUMBER(SEARCH("XFR",N10,1)),"XFR",IF(H10>0,"RCT","WDL"))))) -> WDL | L10: =VLOOKUP(D10,'Entity Code'!A:B,2,0) -> LCC | N10: Stock Repurchase | O10: LCC -3595-0000-000- | P10: N/A | Q10: SS&C to post
B11: 7 | C11: JPM | D11: LADDER CAPITAL FINANCE LLC OPERATIN | E11: 865357602 | F11: 45964 | G11: Debit | H11: -7588.75 | I11: 6825200307JO | J11: FEDWIRE DEBIT | K11: =IF(ISNUMBER(SEARCH("Manual Payment - ",N11,1)),"AP",IF(ISNUMBER(SEARCH("Payment - Concur",N11,1)),"WDL",IF(ISNUMBER(SEARCH("Payroll Transfer",N11,1)),"XFR",IF(ISNUMBER(SEARCH("XFR",N11,1)),"XFR",IF(H11>0,"RCT","WDL"))))) -> AP | L11: =VLOOKUP(D11,'Entity Code'!A:B,2,0) -> LCF | N11: Manual Payment - IT Consultant Agreement | O11: N/A | P11: N/A | Q11: Ladder to post
B12: 8 | C12: PNC | D12: Ladder Capital Finance | E12: 8026459916 | F12: 45964 | G12: CR | H12: 0.03 | I12: '00000000000 | J12: INTEREST ADJUSTMENT CREDIT EFFECTIVE DATE 10-31-25 | K12: =IF(ISNUMBER(SEARCH("Manual Payment - ",N12,1)),"AP",IF(ISNUMBER(SEARCH("Payment - Concur",N12,1)),"WDL",IF(ISNUMBER(SEARCH("Payroll Transfer",N12,1)),"XFR",IF(ISNUMBER(SEARCH("XFR",N12,1)),"XFR",IF(H12>0,"RCT","WDL"))))) -> RCT | L12: =VLOOKUP(D12,'Entity Code'!A:B,2,0) -> LCF | N12: Interest Income - PNC | O12: 4101-0000-000 | P12: N/A | Q12: SS&C to post
B13: 9 | C13: PNC | D13: Tuebor TRS4 | E13: 8180060487 | F13: 45964 | G13: CR | H13: 0.03 | I13: '00000000000 | J13: INTEREST ADJUSTMENT CREDIT EFFECTIVE DATE 10-31-25 | K13: =IF(ISNUMBER(SEARCH("Manual Payment - ",N13,1)),"AP",IF(ISNUMBER(SEARCH("Payment - Concur",N13,1)),"WDL",IF(ISNUMBER(SEARCH("Payroll Transfer",N13,1)),"XFR",IF(ISNUMBER(SEARCH("XFR",N13,1)),"XFR",IF(H13>0,"RCT","WDL"))))) -> RCT | L13: =VLOOKUP(D13,'Entity Code'!A:B,2,0) -> TUET4 | N13: Interest Income - PNC | O13: 4101-0000-000 | P13: N/A | Q13: SS&C to post
B14: 10 | C14: PNC | D14: Ladder Capital Finance | E14: 8026459916 | F14: 45964 | G14: CR | H14: 737.67 | I14: '00000000000 | J14: INTEREST TRANSFER FROM 000008180452958 EFFECTIVE D | K14: =IF(ISNUMBER(SEARCH("Manual Payment - ",N14,1)),"AP",IF(ISNUMBER(SEARCH("Payment - Concur",N14,1)),"WDL",IF(ISNUMBER(SEARCH("Payroll Transfer",N14,1)),"XFR",IF(ISNUMBER(SEARCH("XFR",N14,1)),"XFR",IF(H14>0,"RCT","WDL"))))) -> RCT | L14: =VLOOKUP(D14,'Entity Code'!A:B,2,0) -> LCF | N14: Interest Income - PNC | O14: 4101-0000-000 | P14: N/A | Q14: SS&C to post
B15: 11 | C15: PNC | D15: Tuebor TRS4 | E15: 8180060487 | F15: 45964 | G15: CR | H15: 737.67 | I15: '00000000000 | J15: INTEREST TRANSFER FROM 000008180452966 EFFECTIVE D | K15: =IF(ISNUMBER(SEARCH("Manual Payment - ",N15,1)),"AP",IF(ISNUMBER(SEARCH("Payment - Concur",N15,1)),"WDL",IF(ISNUMBER(SEARCH("Payroll Transfer",N15,1)),"XFR",IF(ISNUMBER(SEARCH("XFR",N15,1)),"XFR",IF(H15>0,"RCT","WDL"))))) -> RCT | L15: =VLOOKUP(D15,'Entity Code'!A:B,2,0) -> TUET4 | N15: Interest Income - PNC | O15: 4101-0000-000 | P15: N/A | Q15: SS&C to post
B16: 12 | C16: JPM | D16: LADDER CAPITAL CRE EQUITY LLC | E16: 528280121 | F16: 45964 | G16: Credit | H16: 1260.7 | I16: 0166141307FC | J16: CHIPS CREDIT | K16: =IF(ISNUMBER(SEARCH("Manual Payment - ",N16,1)),"AP",IF(ISNUMBER(SEARCH("Payment - Concur",N16,1)),"WDL",IF(ISNUMBER(SEARCH("Payroll Transfer",N16,1)),"XFR",IF(ISNUMBER(SEARCH("XFR",N16,1)),"XFR",IF(H16>0,"RCT","WDL"))))) -> RCT | L16: =VLOOKUP(D16,'Entity Code'!A:B,2,0) -> LCREE | N16: Nov RE Remit - DGCAT | O16: LCREE-1470-0000-000-DGCAT | P16: N/A | Q16: Ladder to post
B17: 13 | C17: PNC | D17: CRE EQUITY | E17: 8026496039 | F17: 45964 | G17: CR | H17: 50833.33 | I17: '25304009889690 | J17: ACH CREDIT RECEIVED - Cust ID: 3186050 Desc: PAYME | K17: =IF(ISNUMBER(SEARCH("Manual Payment - ",N17,1)),"AP",IF(ISNUMBER(SEARCH("Payment - Concur",N17,1)),"WDL",IF(ISNUMBER(SEARCH("Payroll Transfer",N17,1)),"XFR",IF(ISNUMBER(SEARCH("XFR",N17,1)),"XFR",IF(H17>0,"RCT","WDL"))))) -> RCT | L17: =VLOOKUP(D17,'Entity Code'!A:B,2,0) -> LCREE | N17: Rental Income - ASEVA | O17: LCREE-1470-0000-000-ASEVA | P17: N/A | Q17: Ladder to post
B18: 13 | C18: PNC | D18: CRE EQUITY | E18: 8026496039 | F18: 45964 | G18: CR | H18: 36916.66 | I18: '25304008009706 | J18: ACH CREDIT RECEIVED - Cust ID: 2000384175 Desc: PA | K18: =IF(ISNUMBER(SEARCH("Manual Payment - ",N18,1)),"AP",IF(ISNUMBER(SEARCH("Payment - Concur",N18,1)),"WDL",IF(ISNUMBER(SEARCH("Payroll Transfer",N18,1)),"XFR",IF(ISNUMBER(SEARCH("XFR",N18,1)),"XFR",IF(H18>0,"RCT","WDL"))))) -> RCT | L18: =VLOOKUP(D18,'Entity Code'!A:B,2,0) -> LCREE | N18: Rental Income - LLBGA | O18: LCREE-1470-0000-000-LLBGA | P18: N/A | Q18: Ladder to post
B19: 13 | C19: PNC | D19: CRE EQUITY | E19: 8026496039 | F19: 45964 | G19: CR | H19: 33250 | I19: '25304008009768 | J19: ACH CREDIT RECEIVED - Cust ID: 2000385535 Desc: PA | K19: =IF(ISNUMBER(SEARCH("Manual Payment - ",N19,1)),"AP",IF(ISNUMBER(SEARCH("Payment - Concur",N19,1)),"WDL",IF(ISNUMBER(SEARCH("Payroll Transfer",N19,1)),"XFR",IF(ISNUMBER(SEARCH("XFR",N19,1)),"XFR",IF(H19>0,"RCT","WDL"))))) -> RCT | L19: =VLOOKUP(D19,'Entity Code'!A:B,2,0) -> LCREE | N19: Rental Income - WGHI2 | O19: LCREE-1470-0000-000-WGHI2 | P19: N/A | Q19: Ladder to post
B20: 13 | C20: PNC | D20: CRE EQUITY | E20: 8026496039 | F20: 45964 | G20: CR | H20: 27083.33 | I20: '25304008009758 | J20: ACH CREDIT RECEIVED - Cust ID: 2000385534 Desc: PA | K20: =IF(ISNUMBER(SEARCH("Manual Payment - ",N20,1)),"AP",IF(ISNUMBER(SEARCH("Payment - Concur",N20,1)),"WDL",IF(ISNUMBER(SEARCH("Payroll Transfer",N20,1)),"XFR",IF(ISNUMBER(SEARCH("XFR",N20,1)),"XFR",IF(H20>0,"RCT","WDL"))))) -> RCT | L20: =VLOOKUP(D20,'Entity Code'!A:B,2,0) -> LCREE | N20: Rental Income - WGNI2 | O20: LCREE-1470-0000-000-WGNI2 | P20: N/A | Q20: Ladder to post
B21: 14 | C21: PNC | D21: LCR 3 | E21: 8026496047 | F21: 45964 | G21: CR | H21: 16160000 | I21: '25B3H5621O900KJO | J21: WIRE TRANSFER ISO AMT:USD 16160000.00 STTLMT DATE: | K21: =IF(ISNUMBER(SEARCH("Manual Payment - ",N21,1)),"AP",IF(ISNUMBER(SEARCH("Payment - Concur",N21,1)),"WDL",IF(ISNUMBER(SEARCH("Payroll Transfer",N21,1)),"XFR",IF(ISNUMBER(SEARCH("XFR",N21,1)),"XFR",IF(H21>0,"RCT","WDL"))))) -> RCT | L21: =VLOOKUP(D21,'Entity Code'!A:B,2,0) -> LCR3 | N21: Group RMC Partial Paydown | O21: 2701-LMS0-000 | P21: N/A | Q21: SS&C to post
B22: 15 | C22: PNC | D22: LCR 3 | E22: 8026496047 | F22: 45964 | G22: CR | H22: 183000 | I22: '25B3F225304Z29WA | J22: BOOK TRANSFER CREDIT 0029WA ORIGINATOR:LADDER CAPI | K22: =IF(ISNUMBER(SEARCH("Manual Payment - ",N22,1)),"AP",IF(ISNUMBER(SEARCH("Payment - Concur",N22,1)),"WDL",IF(ISNUMBER(SEARCH("Payroll Transfer",N22,1)),"XFR",IF(ISNUMBER(SEARCH("XFR",N22,1)),"XFR",IF(H22>0,"RCT","WDL"))))) -> XFR | L22: =VLOOKUP(D22,'Entity Code'!A:B,2,0) -> LCR3 | N22: XFR from LCFHR PNC to LCR3 PNC | O22: 2701-CAMR-000 | P22: N/A | Q22: SS&C to post
B23: 15 | C23: PNC | D23: LCFH REIT | E23: 8026459924 | F23: 45964 | G23: DR | H23: -183000 | I23: '25B3F225304Z29WA | J23: BOOK TRANSFER DEBIT 0029WA ORIGINATOR:LADDER CAPIT | K23: =IF(ISNUMBER(SEARCH("Manual Payment - ",N23,1)),"AP",IF(ISNUMBER(SEARCH("Payment - Concur",N23,1)),"WDL",IF(ISNUMBER(SEARCH("Payroll Transfer",N23,1)),"XFR",IF(ISNUMBER(SEARCH("XFR",N23,1)),"XFR",IF(H23>0,"RCT","WDL"))))) -> XFR | L23: =VLOOKUP(D23,'Entity Code'!A:B,2,0) -> LCFHR | N23: XFR from LCFHR PNC to LCR3 PNC | O23: 2701-CAMR-000 | P23: N/A | Q23: SS&C to post
B24: 16 | C24: PNC | D24: LCC | E24: 8026482868 | F24: 45964 | G24: CR | H24: 52732 | I24: '25B3F2252P104G6G | J24: BOOK TRANSFER CREDIT 004G6G ORIGINATOR:LADDER CAPI | K24: =IF(ISNUMBER(SEARCH("Manual Payment - ",N24,1)),"AP",IF(ISNUMBER(SEARCH("Payment - Concur",N24,1)),"WDL",IF(ISNUMBER(SEARCH("Payroll Transfer",N24,1)),"XFR",IF(ISNUMBER(SEARCH("XFR",N24,1)),"XFR",IF(H24>0,"RCT","WDL"))))) -> XFR | L24: =VLOOKUP(D24,'Entity Code'!A:B,2,0) -> LCC | N24: XFR from LCFHR PNC to LCC | O24: 2701-CAMR-000 | P24: N/A | Q24: SS&C to post
B25: 16 | C25: PNC | D25: LCFH REIT | E25: 8026459924 | F25: 45964 | G25: DR | H25: -52732 | I25: '25B3F2252P104G6G | J25: BOOK TRANSFER DEBIT 004G6G ORIGINATOR:LADDER CAPIT | K25: =IF(ISNUMBER(SEARCH("Manual Payment - ",N25,1)),"AP",IF(ISNUMBER(SEARCH("Payment - Concur",N25,1)),"WDL",IF(ISNUMBER(SEARCH("Payroll Transfer",N25,1)),"XFR",IF(ISNUMBER(SEARCH("XFR",N25,1)),"XFR",IF(H25>0,"RCT","WDL"))))) -> XFR | L25: =VLOOKUP(D25,'Entity Code'!A:B,2,0) -> LCFHR | N25: XFR from LCFHR PNC to LCC | O25: 2701-CAMR-000 | P25: N/A | Q25: SS&C to post
B26: 17 | C26: PNC | D26: LCI | E26: 8026496012 | F26: 45964 | G26: CR | H26: 50000 | I26: '25B3F22537PZ19WC | J26: BOOK TRANSFER CREDIT 0019WC ORIGINATOR:LADDER CAPI | K26: =IF(ISNUMBER(SEARCH("Manual Payment - ",N26,1)),"AP",IF(ISNUMBER(SEARCH("Payment - Concur",N26,1)),"WDL",IF(ISNUMBER(SEARCH("Payroll Transfer",N26,1)),"XFR",IF(ISNUMBER(SEARCH("XFR",N26,1)),"XFR",IF(H26>0,"RCT","WDL"))))) -> XFR | L26: =VLOOKUP(D26,'Entity Code'!A:B,2,0) -> LCI | N26: XFR from LCFHR PNC to LCI PNC | O26: 2701-CAMR-000 | P26: N/A | Q26: SS&C to post
B27: 17 | C27: PNC | D27: LCFH REIT | E27: 8026459924 | F27: 45964 | G27: DR | H27: -50000 | I27: '25B3F22537PZ19WC | J27: BOOK TRANSFER DEBIT 0019WC ORIGINATOR:LADDER CAPIT | K27: =IF(ISNUMBER(SEARCH("Manual Payment - ",N27,1)),"AP",IF(ISNUMBER(SEARCH("Payment - Concur",N27,1)),"WDL",IF(ISNUMBER(SEARCH("Payroll Transfer",N27,1)),"XFR",IF(ISNUMBER(SEARCH("XFR",N27,1)),"XFR",IF(H27>0,"RCT","WDL"))))) -> XFR | L27: =VLOOKUP(D27,'Entity Code'!A:B,2,0) -> LCFHR | N27: XFR from LCFHR PNC to LCI PNC | O27: 2701-CAMR-000 | P27: N/A | Q27: SS&C to post
B28: 18 | C28: PNC | D28: LCI | E28: 8026496012 | F28: 45964 | G28: DR | H28: -50000 | I28: 'PAB3C46274DJ0BGR | J28: WIRE TRANSFER ISO AMT:USD 50000.00 STTLMT DATE:110 | K28: =IF(ISNUMBER(SEARCH("Manual Payment - ",N28,1)),"AP",IF(ISNUMBER(SEARCH("Payment - Concur",N28,1)),"WDL",IF(ISNUMBER(SEARCH("Payroll Transfer",N28,1)),"XFR",IF(ISNUMBER(SEARCH("XFR",N28,1)),"XFR",IF(H28>0,"RCT","WDL"))))) -> XFR | L28: =VLOOKUP(D28,'Entity Code'!A:B,2,0) -> LCI | N28: XFR from LCI PNC to LCFP Equity PB | O28: 2701-CAMR-000 | P28: N/A | Q28: SS&C to post
... B32: 21 | C32: PNC | D32: LCFH REIT | E32: 8026459924 | F32: 45964 | G32: CR | H32: 8000000 | I32: '25B3H5215MTZ08EG | J32: WIRE TRANSFER ISO STTLMT DATE:11032025 CLR SYS REF | K32: =IF(ISNUMBER(SEARCH("Manual Payment - ",N32,1)),"AP",IF(ISNUMBER(SEARCH("Payment - Concur",N32,1)),"WDL",IF(ISNUMBER(SEARCH("Payroll Transfer",N32,1)),"XFR",IF(ISNUMBER(SEARCH("XFR",N32,1)),"XFR",IF(H32>0,"RCT","WDL"))))) -> XFR | L32: =VLOOKUP(D32,'Entity Code'!A:B,2,0) -> LCFHR | N32: XFR from LCFHR BNY to LCFHR PNC | O32: 2701-CAMR-000 | P32: N/A | Q32: SS&C to post
B33: 22 | C33: JPM | D33: LADDER CAPITAL FINANCE LLC OPERATIN | E33: 865357602 | F33: 45964 | G33: Debit | H33: -1187.5 | I33: 0063500304VB | J33: FEDWIRE DEBIT | K33: =IF(ISNUMBER(SEARCH("Manual Payment - ",N33,1)),"AP",IF(ISNUMBER(SEARCH("Payment - Concur",N33,1)),"WDL",IF(ISNUMBER(SEARCH("Payroll Transfer",N33,1)),"XFR",IF(ISNUMBER(SEARCH("XFR",N33,1)),"XFR",IF(H33>0,"RCT","WDL"))))) -> AP | L33: =VLOOKUP(D33,'Entity Code'!A:B,2,0) -> LCF | N33: Manual Payment - Rosenberg & Estis | O33: N/A | P33: N/A | Q33: Ladder to post
B34: 23 | C34: JPM | D34: LADDER CAPITAL FINANCE LLC OPERATIN | E34: 865357602 | F34: 45964 | G34: Debit | H34: -8701.28 | I34: 3079172302TC | J34: EFT DEBIT | K34: =IF(ISNUMBER(SEARCH("Manual Payment - ",N34,1)),"AP",IF(ISNUMBER(SEARCH("Payment - Concur",N34,1)),"WDL",IF(ISNUMBER(SEARCH("Payroll Transfer",N34,1)),"XFR",IF(ISNUMBER(SEARCH("XFR",N34,1)),"XFR",IF(H34>0,"RCT","WDL"))))) -> AP | L34: =VLOOKUP(D34,'Entity Code'!A:B,2,0) -> LCF | N34: Manual Payment - The New West Con | O34: N/A | P34: N/A | Q34: Ladder to post
B35: 24 | C35: JPM | D35: LADDER CAPITAL FINANCE LLC OPERATIN | E35: 865357602 | F35: 45964 | G35: Debit | H35: -5935 | I35: 3079172300TC | J35: EFT DEBIT | K35: =IF(ISNUMBER(SEARCH("Manual Payment - ",N35,1)),"AP",IF(ISNUMBER(SEARCH("Payment - Concur",N35,1)),"WDL",IF(ISNUMBER(SEARCH("Payroll Transfer",N35,1)),"XFR",IF(ISNUMBER(SEARCH("XFR",N35,1)),"XFR",IF(H35>0,"RCT","WDL"))))) -> AP | L35: =VLOOKUP(D35,'Entity Code'!A:B,2,0) -> LCF | N35: Manual Payment - Industrious office | O35: N/A | P35: N/A | Q35: Ladder to post
B36: 25 | C36: JPM | D36: LADDER CAPITAL FINANCE LLC OPERATIN | E36: 865357602 | F36: 45964 | G36: Debit | H36: -191680.03 | I36: 0049100304VB | J36: BOOK TRANSFER DEBIT | K36: =IF(ISNUMBER(SEARCH("Manual Payment - ",N36,1)),"AP",IF(ISNUMBER(SEARCH("Payment - Concur",N36,1)),"WDL",IF(ISNUMBER(SEARCH("Payroll Transfer",N36,1)),"XFR",IF(ISNUMBER(SEARCH("XFR",N36,1)),"XFR",IF(H36>0,"RCT","WDL"))))) -> AP | L36: =VLOOKUP(D36,'Entity Code'!A:B,2,0) -> LCF | N36: Manual Payment - 320 Park Ave | O36: N/A | P36: N/A | Q36: Ladder to post
B37: 26 | C37: JPM | D37: LADDER CAPITAL FINANCE LLC OPERATIN | E37: 865357602 | F37: 45964 | G37: Debit | H37: -23192.55 | I37: 0049200304VB | J37: BOOK TRANSFER DEBIT | K37: =IF(ISNUMBER(SEARCH("Manual Payment - ",N37,1)),"AP",IF(ISNUMBER(SEARCH("Payment - Concur",N37,1)),"WDL",IF(ISNUMBER(SEARCH("Payroll Transfer",N37,1)),"XFR",IF(ISNUMBER(SEARCH("XFR",N37,1)),"XFR",IF(H37>0,"RCT","WDL"))))) -> AP | L37: =VLOOKUP(D37,'Entity Code'!A:B,2,0) -> LCF | N37: Manual Payment - AMEX | O37: N/A | P37: N/A | Q37: Ladder to post

Sheet Cash Entries 11-3
A1: ENTITY | B1: YEARMONTH | C1: SOURCE | D1: BATCH ID | E1: BATCH DESCRIPTION | F1: BATCHDATE | G1: DR_AMT | H1: CR AMT | I1: TRXDATE | J1: DIST REFERENCE | K1: GPACCT
A2: LCREE | B2: =Checklist!$B$1 -> 202511 | C2: GJ | D2: =Checklist!$B$5 -> DC1103251 | E2: =D2 -> DC1103251 | F2: =Checklist!$A$5 -> 45964 | G2: 1260.7 | H2: 0 | I2: =$F$2 -> 45964 | J2: Nov RE Remit - DGCAT | K2: LCREE-1043-0000-000-
A3: LCREE | B3: =Checklist!$B$1 -> 202511 | C3: GJ | D3: =D2 -> DC1103251 | E3: =D3 -> DC1103251 | F3: =$F$2 -> 45964 | G3: 0 | H3: 1260.7 | I3: =$F$2 -> 45964 | J3: Nov RE Remit - DGCAT | K3: LCREE-1470-0000-000-DGCAT
A4: LCREE | B4: =Checklist!$B$1 -> 202511 | C4: GJ | D4: =D3 -> DC1103251 | E4: =D4 -> DC1103251 | F4: =$F$2 -> 45964 | G4: 50833.33 | H4: 0 | I4: =$F$2 -> 45964 | J4: Rental Income - ASEVA | K4: LCREE-1065-0008-000-
A5: LCREE | B5: =Checklist!$B$1 -> 202511 | C5: GJ | D5: =D4 -> DC1103251 | E5: =D5 -> DC1103251 | F5: =$F$2 -> 45964 | G5: 0 | H5: 50833.33 | I5: =$F$2 -> 45964 | J5: Rental Income - ASEVA | K5: LCREE-1470-0000-000-ASEVA
A6: LCREE | B6: =Checklist!$B$1 -> 202511 | C6: GJ | D6: =D5 -> DC1103251 | E6: =D6 -> DC1103251 | F6: =$F$2 -> 45964 | G6: 36916.66 | H6: 0 | I6: =$F$2 -> 45964 | J6: Rental Income - LLBGA | K6: LCREE-1065-0008-000-
A7: LCREE | B7: =Checklist!$B$1 -> 202511 | C7: GJ | D7: =D6 -> DC1103251 | E7: =D7 -> DC1103251 | F7: =$F$2 -> 45964 | G7: 0 | H7: 36916.66 | I7: =$F$2 -> 45964 | J7: Rental Income - LLBGA | K7: LCREE-1470-0000-000-LLBGA
A8: LCREE | B8: =Checklist!$B$1 -> 202511 | C8: GJ | D8: =D7 -> DC1103251 | E8: =D8 -> DC1103251 | F8: =$F$2 -> 45964 | G8: 33250 | H8: 0 | I8: =$F$2 -> 45964 | J8: Rental Income - WGHI2 | K8: LCREE-1065-0008-000-
A9: LCREE | B9: =Checklist!$B$1 -> 202511 | C9: GJ | D9: =D8 -> DC1103251 | E9: =D9 -> DC1103251 | F9: =$F$2 -> 45964 | G9: 0 | H9: 33250 | I9: =$F$2 -> 45964 | J9: Rental Income - WGHI2 | K9: LCREE-1470-0000-000-WGHI2
A10: LCREE | B10: =Checklist!$B$1 -> 202511 | C10: GJ | D10: =D9 -> DC1103251 | E10: =D10 -> DC1103251 | F10: =$F$2 -> 45964 | G10: 27083.33 | H10: 0 | I10: =$F$2 -> 45964 | J10: Rental Income - WGNI2 | K10: LCREE-1065-0008-000-
A11: LCREE | B11: =Checklist!$B$1 -> 202511 | C11: GJ | D11: =D10 -> DC1103251 | E11: =D11 -> DC1103251 | F11: =$F$2 -> 45964 | G11: 0 | H11: 27083.33 | I11: =$F$2 -> 45964 | J11: Rental Income - WGNI2 | K11: LCREE-1470-0000-000-WGNI2
B12: =Checklist!$B$1 -> 202511 | C12: GJ | D12: =D11 -> DC1103251 | E12: =D12 -> DC1103251 | F12: =$F$2 -> 45964 | I12: =$F$2 -> 45964
B13: =Checklist!$B$1 -> 202511 | C13: GJ | D13: =D12 -> DC1103251 | E13: =D13 -> DC1103251 | F13: =$F$2 -> 45964 | I13: =$F$2 -> 45964
B14: =Checklist!$B$1 -> 202511 | C14: GJ | D14: =D13 -> DC1103251 | E14: =D14 -> DC1103251 | F14: =$F$2 -> 45964 | I14: =$F$2 -> 45964
B15: =Checklist!$B$1 -> 202511 | C15: GJ | D15: =D14 -> DC1103251 | E15: =D15 -> DC1103251 | F15: =$F$2 -> 45964 | I15: =$F$2 -> 45964
B16: =Checklist!$B$1 -> 202511 | C16: GJ | D16: =D15 -> DC1103251 | E16: =D16 -> DC1103251 | F16: =$F$2 -> 45964 | I16: =$F$2 -> 45964
B17: =Checklist!$B$1 -> 202511 | C17: GJ | D17: =D16 -> DC1103251 | E17: =D17 -> DC1103251 | F17: =$F$2 -> 45964 | I17: =$F$2 -> 45964
B18: =Checklist!$B$1 -> 202511 | C18: GJ | D18: =D17 -> DC1103251 | E18: =D18 -> DC1103251 | F18: =$F$2 -> 45964 | I18: =$F$2 -> 45964
B19: =Checklist!$B$1 -> 202511 | C19: GJ | D19: =D18 -> DC1103251 | E19: =D19 -> DC1103251 | F19: =$F$2 -> 45964 | I19: =$F$2 -> 45964
B20: =Checklist!$B$1 -> 202511 | C20: GJ | D20: =D19 -> DC1103251 | E20: =D20 -> DC1103251 | F20: =$F$2 -> 45964 | I20: =$F$2 -> 45964
B21: =Checklist!$B$1 -> 202511 | C21: GJ | D21: =D20 -> DC1103251 | E21: =D21 -> DC1103251 | F21: =$F$2 -> 45964 | I21: =$F$2 -> 45964
B22: =Checklist!$B$1 -> 202511 | C22: GJ | D22: =D21 -> DC1103251 | E22: =D22 -> DC1103251 | F22: =$F$2 -> 45964 | I22: =$F$2 -> 45964
B23: =Checklist!$B$1 -> 202511 | C23: GJ | D23: =D22 -> DC1103251 | E23: =D23 -> DC1103251 | F23: =$F$2 -> 45964 | I23: =$F$2 -> 45964
... B25: =Checklist!$B$1 -> 202511 | C25: GJ | D25: =D24 -> DC1103251 | E25: =D25 -> DC1103251 | F25: =$F$2 -> 45964 | I25: =$F$2 -> 45964

Sheet Cash Activity 11-4
A1: ="Daily Bank Activity - "&MONTH(Checklist!A6)&"/"&DAY(Checklist!A6)&"/"&YEAR(Checklist!A6) -> Daily Bank Activity - 11/4/2025
A2: Credit (+) / Debit (-)
B4: # | C4: Bank | D4: Acct Name | E4: Acct # | F4: Date | G4: Type | H4: Amount | I4: Bank Ref | J4: Bank Stmt Description | K4: Trans Type | L4: Entity | M4: AIT | N4: Short Description | O4: GL Account 1 | P4: GL Account 2 | Q4: Posted?
B5: 1 | C5: PNC | D5: LCFH REIT | E5: 8026459924 | F5: 45965 | G5: CR | H5: 211.66 | I5: '00000000000 | J5: PNC SWEEP INTEREST @ 0.000000 EFFECTIVE DATE 11-03 | K5: =IF(ISNUMBER(SEARCH("Manual Payment - ",N5,1)),"AP",IF(ISNUMBER(SEARCH("Payment - Concur",N5,1)),"WDL",IF(ISNUMBER(SEARCH("Payroll Transfer",N5,1)),"XFR",IF(ISNUMBER(SEARCH("XFR",N5,1)),"XFR",IF(H5>0,"RCT","WDL"))))) -> RCT | L5: =VLOOKUP(D5,'Entity Code'!A:B,2,0) -> LCFHR | N5: Overnight interest sweep PNC LCFHR account. No entry required | O5: N/A | P5: N/A | Q5: N/A
B6: 2 | C6: PNC | D6: LCFH REIT | E6: 8026459924 | F6: 45965 | G6: CR | H6: 2452621.7 | I6: '00000000000 | J6: SWEEP TRANSFR FROM INVESTMENT ACCT 8026459924 | K6: =IF(ISNUMBER(SEARCH("Manual Payment - ",N6,1)),"AP",IF(ISNUMBER(SEARCH("Payment - Concur",N6,1)),"WDL",IF(ISNUMBER(SEARCH("Payroll Transfer",N6,1)),"XFR",IF(ISNUMBER(SEARCH("XFR",N6,1)),"XFR",IF(H6>0,"RCT","WDL"))))) -> RCT | L6: =VLOOKUP(D6,'Entity Code'!A:B,2,0) -> LCFHR | N6: Overnight interest sweep PNC LCFHR account. No entry required | O6: N/A | P6: N/A | Q6: N/A
B7: 3 | C7: PNC | D7: LCFH REIT | E7: 8026459924 | F7: 45965 | G7: DR | H7: -5072833.3 | I7: '00000000000 | J7: SWEEP TO INVESTMENT ACCT# 8026459924 | K7: =IF(ISNUMBER(SEARCH("Manual Payment - ",N7,1)),"AP",IF(ISNUMBER(SEARCH("Payment - Concur",N7,1)),"WDL",IF(ISNUMBER(SEARCH("Payroll Transfer",N7,1)),"XFR",IF(ISNUMBER(SEARCH("XFR",N7,1)),"XFR",IF(H7>0,"RCT","WDL"))))) -> WDL | L7: =VLOOKUP(D7,'Entity Code'!A:B,2,0) -> LCFHR | N7: Overnight interest sweep PNC LCFHR account. No entry required | O7: N/A | P7: N/A | Q7: N/A
B8: 4 | C8: PNC | D8: LCFH REIT | E8: 8026459924 | F8: 45965 | G8: DR | H8: -10000000 | I8: 'PAB4C4927P7I4RWJ | J8: WIRE TRANSFER ISO AMT:USD 10000000.00 STTLMT DATE: | K8: =IF(ISNUMBER(SEARCH("Manual Payment - ",N8,1)),"AP",IF(ISNUMBER(SEARCH("Payment - Concur",N8,1)),"WDL",IF(ISNUMBER(SEARCH("Payroll Transfer",N8,1)),"XFR",IF(ISNUMBER(SEARCH("XFR",N8,1)),"XFR",IF(H8>0,"RCT","WDL"))))) -> WDL | L8: =VLOOKUP(D8,'Entity Code'!A:B,2,0) -> LCFHR | N8: SocGen Paydown | O8: 2701-CAMR-000 | P8: N/A | Q8: SS&C to post
B9: 5 | C9: PNC | D9: Tuebor REIT | E9: 8026495976 | F9: 45965 | G9: DR | H9: -182796.41 | I9: '25B3N0050C3Z52A1 | J9: WIRE TRANSFER ISO STTLMT DATE:11042025 CLR SYS REF | K9: =IF(ISNUMBER(SEARCH("Manual Payment - ",N9,1)),"AP",IF(ISNUMBER(SEARCH("Payment - Concur",N9,1)),"WDL",IF(ISNUMBER(SEARCH("Payroll Transfer",N9,1)),"XFR",IF(ISNUMBER(SEARCH("XFR",N9,1)),"XFR",IF(H9>0,"RCT","WDL"))))) -> WDL | L9: =VLOOKUP(D9,'Entity Code'!A:B,2,0) -> TUERI | N9: Incorrect advance wire – refund expected | O9: =IFERROR(VLOOKUP(E9,'Bank Account'!A:B,2,FALSE),VLOOKUP(_xlfn.NUMBERVALUE(E9),'Bank Account'!A:B,2,FALSE)) -> TUERI-1065-0010-000-
B10: 6 | C10: JPM | D10: LADDER CAPITAL FINANCE LLC TRADING | E10: 865357610 | F10: 45965 | G10: Credit | H10: 13774.39 | I10: 3580941602 | J10: REMOTE ONLINE DEP | K10: =IF(ISNUMBER(SEARCH("Manual Payment - ",N10,1)),"AP",IF(ISNUMBER(SEARCH("Payment - Concur",N10,1)),"WDL",IF(ISNUMBER(SEARCH("Payroll Transfer",N10,1)),"XFR",IF(ISNUMBER(SEARCH("XFR",N10,1)),"XFR",IF(H10>0,"RCT","WDL"))))) -> RCT | L10: =VLOOKUP(D10,'Entity Code'!A:B,2,0) -> LCF | N10: Checks Deposited - employee expense reimbursement, IMA and Meridian Mark management fee share | O10: Various | Q10: Ladder to post
B11: 7 | C11: JPM | D11: LADDER CAPITAL CRE EQUITY LLC | E11: 528280121 | F11: 45965 | G11: Credit | H11: 40930.28 | I11: 3580941587 | J11: REMOTE ONLINE DEP | K11: =IF(ISNUMBER(SEARCH("Manual Payment - ",N11,1)),"AP",IF(ISNUMBER(SEARCH("Payment - Concur",N11,1)),"WDL",IF(ISNUMBER(SEARCH("Payroll Transfer",N11,1)),"XFR",IF(ISNUMBER(SEARCH("XFR",N11,1)),"XFR",IF(H11>0,"RCT","WDL"))))) -> RCT | L11: =VLOOKUP(D11,'Entity Code'!A:B,2,0) -> LCREE | N11: Checks Deposited - DG De Soto, Warren, Tremont and Effingham | O11: Various | P11: N/A | Q11: Ladder to post
B12: 8 | C12: JPM | D12: LADDER CAPITAL CRE EQUITY LLC | E12: 528280121 | F12: 45965 | G12: Credit | H12: 46666.67 | I12: 3580941596 | J12: REMOTE ONLINE DEP | K12: =IF(ISNUMBER(SEARCH("Manual Payment - ",N12,1)),"AP",IF(ISNUMBER(SEARCH("Payment - Concur",N12,1)),"WDL",IF(ISNUMBER(SEARCH("Payroll Transfer",N12,1)),"XFR",IF(ISNUMBER(SEARCH("XFR",N12,1)),"XFR",IF(H12>0,"RCT","WDL"))))) -> RCT | L12: =VLOOKUP(D12,'Entity Code'!A:B,2,0) -> LCREE | N12: Rental Income - WGPON | O12: LCREE-1470-0000-000-WGPON | P12: N/A | Q12: Ladder to post
B13: 9 | C13: PNC | D13: LCREF | E13: 8026497285 | F13: 45965 | G13: CR | H13: 350000 | I13: '25B4L1857BC14LOY | J13: WIRE TRANSFER ISO AMT:USD 350000.00 STTLMT DATE:11 | K13: =IF(ISNUMBER(SEARCH("Manual Payment - ",N13,1)),"AP",IF(ISNUMBER(SEARCH("Payment - Concur",N13,1)),"WDL",IF(ISNUMBER(SEARCH("Payroll Transfer",N13,1)),"XFR",IF(ISNUMBER(SEARCH("XFR",N13,1)),"XFR",IF(H13>0,"RCT","WDL"))))) -> RCT | L13: =VLOOKUP(D13,'Entity Code'!A:B,2,0) -> LCREF | N13: 519 Uptown Owner's Account Excess Funds | O13: LCREF-1470-0000-000-519UP | P13: N/A | Q13: Ladder to post
B14: 10 | C14: PNC | D14: Tuebor REIT | E14: 8026495976 | F14: 45965 | G14: CR | H14: 1400000 | I14: '25B4K3538I8Z8EMF | J14: WIRE TRANSFER ISO AMT:USD 1400000.00 STTLMT DATE:1 | K14: =IF(ISNUMBER(SEARCH("Manual Payment - ",N14,1)),"AP",IF(ISNUMBER(SEARCH("Payment - Concur",N14,1)),"WDL",IF(ISNUMBER(SEARCH("Payroll Transfer",N14,1)),"XFR",IF(ISNUMBER(SEARCH("XFR",N14,1)),"XFR",IF(H14>0,"RCT","WDL"))))) -> RCT | L14: =VLOOKUP(D14,'Entity Code'!A:B,2,0) -> TUERI | N14: 15600 JFK Owner's Account Excess Funds | O14: TUERI-1470-0000-000-15JFK | P14: N/A | Q14: Ladder to post
B15: 11 | C15: PNC | D15: LCFH REIT | E15: 8026459924 | F15: 45965 | G15: CR | H15: 22520000 | I15: '25B4H00479K111UZ | J15: WIRE TRANSFER ISO STTLMT DATE:11042025 CLR SYS REF | K15: =IF(ISNUMBER(SEARCH("Manual Payment - ",N15,1)),"AP",IF(ISNUMBER(SEARCH("Payment - Concur",N15,1)),"WDL",IF(ISNUMBER(SEARCH("Payroll Transfer",N15,1)),"XFR",IF(ISNUMBER(SEARCH("XFR",N15,1)),"XFR",IF(H15>0,"RCT","WDL"))))) -> XFR | L15: =VLOOKUP(D15,'Entity Code'!A:B,2,0) -> LCFHR | N15: XFR from LCFHR BNY to LCFHR PNC | O15: 2701-CAMR-000 | P15: N/A | Q15: SS&C to post
B16: 12 | C16: PNC | D16: LCFH REIT | E16: 8026459924 | F16: 45965 | G16: DR | H16: -9900000 | I16: 'PAB4C4927PGH3776 | J16: WIRE TRANSFER ISO AMT:USD 9900000.00 STTLMT DATE:1 | K16: =IF(ISNUMBER(SEARCH("Manual Payment - ",N16,1)),"AP",IF(ISNUMBER(SEARCH("Payment - Concur",N16,1)),"WDL",IF(ISNUMBER(SEARCH("Payroll Transfer",N16,1)),"XFR",IF(ISNUMBER(SEARCH("XFR",N16,1)),"XFR",IF(H16>0,"RCT","WDL"))))) -> XFR | L16: =VLOOKUP(D16,'Entity Code'!A:B,2,0) -> LCFHR | N16: XFR from LCFHR PNC to LCFP3 | O16: 2701-CAMR-000 | P16: N/A | Q16: SS&C to post
B17: 13 | C17: JPM | D17: LADDER CAPITAL FINANCE LLC OPERATIN | E17: 865357602 | F17: 45965 | G17: Debit | H17: -10422.54 | I17: 3084101163TC | J17: EFT DEBIT | K17: =IF(ISNUMBER(SEARCH("Manual Payment - ",N17,1)),"AP",IF(ISNUMBER(SEARCH("Payment - Concur",N17,1)),"WDL",IF(ISNUMBER(SEARCH("Payroll Transfer",N17,1)),"XFR",IF(ISNUMBER(SEARCH("XFR",N17,1)),"XFR",IF(H17>0,"RCT","WDL"))))) -> WDL | L17: =VLOOKUP(D17,'Entity Code'!A:B,2,0) -> LCF | N17: Payment - Concur | O17: N/A | P17: N/A | Q17: Ladder to post
B18: 14 | C18: JPM | D18: LADDER CAPITAL FINANCE LLC OPERATIN | E18: 865357602 | F18: 45965 | G18: Debit | H18: -1642.72 | I18: 3084101161TC | J18: EFT DEBIT | K18: =IF(ISNUMBER(SEARCH("Manual Payment - ",N18,1)),"AP",IF(ISNUMBER(SEARCH("Payment - Concur",N18,1)),"WDL",IF(ISNUMBER(SEARCH("Payroll Transfer",N18,1)),"XFR",IF(ISNUMBER(SEARCH("XFR",N18,1)),"XFR",IF(H18>0,"RCT","WDL"))))) -> AP | L18: =VLOOKUP(D18,'Entity Code'!A:B,2,0) -> LCF | N18: Manual Payment - Con Ed | O18: N/A | P18: N/A | Q18: Ladder to post
N23: Check Deposited - employee expense reimbursement | O23: 361.96 | P23: LCF -5405-0000-000-
N24: Check Deposited - IMA | O24: 901.79 | P24: reached out to SG on 11/7
N25: Check Deposited - Meridian Mark management fee share | O25: 12510.64 | P25: LCF -4410-LN03-200-
O26: =SUM(O23:O25) -> 13774.39
O27: =H10 -> 13774.39
O28: =O26-O27 -> 0
N31: Check Deposited - DG - DeSoto IA | O31: 4527.41 | P31: LCREE-1470-0000-000-DGDES
N32: Check Deposited - DG - Warren | O32: 4953.9 | P32: DGWAR-1950-0000-000-
N33: Check Deposited - DG - Tremont IL | O33: 14531 | P33: DGTRE-1950-0000-000-
N34: Check Deposited - DG - Effingham IL | O34: 16917.97 | P34: LCREE-1950-0000-000-
O35: =SUM(O31:O34) -> 40930.28
O36: =H11 -> 40930.28
O37: =O35-O36 -> 0

Sheet Cash Entries 11-4
A1: ENTITY | B1: YEARMONTH | C1: SOURCE | D1: BATCH ID | E1: BATCH DESCRIPTION | F1: BATCHDATE | G1: DR_AMT | H1: CR AMT | I1: TRXDATE | J1: DIST REFERENCE | K1: GPACCT
A2: LCF | B2: =Checklist!$B$1 -> 202511 | C2: GJ | D2: =Checklist!$B$6 -> DC1104251 | E2: =D2 -> DC1104251 | F2: =Checklist!$A$6 -> 45965 | G2: 13774.39 | H2: 0 | I2: =$F$2 -> 45965 | J2: Checks Deposited - employee expense reimbursement, IMA and Meridian Mark management fee share | K2: LCF -1029-0000-000-
A3: LCF | B3: =Checklist!$B$1 -> 202511 | C3: GJ | D3: =D2 -> DC1104251 | E3: =D3 -> DC1104251 | F3: =Checklist!$A$6 -> 45965 | G3: 0 | H3: 361.96 | I3: =$F$2 -> 45965 | J3: Checks Deposited - employee expense reimbursement, IMA and Meridian Mark management fee share | K3: LCF -5405-0000-000- | L3: Check Deposited - employee expense reimbursement
A4: LCF | B4: =Checklist!$B$1 -> 202511 | C4: GJ | D4: =D3 -> DC1104251 | E4: =D4 -> DC1104251 | F4: =Checklist!$A$6 -> 45965 | G4: 0 | H4: 901.79 | I4: =$F$2 -> 45965 | J4: Checks Deposited - employee expense reimbursement, IMA and Meridian Mark management fee share | L4: Check Deposited - IMA
A5: LCF | B5: =Checklist!$B$1 -> 202511 | C5: GJ | D5: =D4 -> DC1104251 | E5: =D5 -> DC1104251 | F5: =Checklist!$A$6 -> 45965 | G5: 0 | H5: 12510.64 | I5: =$F$2 -> 45965 | J5: Checks Deposited - employee expense reimbursement, IMA and Meridian Mark management fee share | K5: LCF -4410-LN03-200- | L5: Check Deposited - Meridian Mark management fee share
A6: LCREE | B6: =Checklist!$B$1 -> 202511 | C6: GJ | D6: =D5 -> DC1104251 | E6: =D6 -> DC1104251 | F6: =Checklist!$A$6 -> 45965 | G6: 40930.28 | H6: 0 | I6: =$F$2 -> 45965 | J6: Checks Deposited - DG De Soto, Warren, Tremont and Effingham | K6: LCREE-1043-0000-000-
A7: LCREE | B7: =Checklist!$B$1 -> 202511 | C7: GJ | D7: =D6 -> DC1104251 | E7: =D7 -> DC1104251 | F7: =Checklist!$A$6 -> 45965 | G7: 0 | H7: 4527.41 | I7: =$F$2 -> 45965 | J7: Checks Deposited - DG De Soto, Warren, Tremont and Effingham | K7: LCREE-1470-0000-000-DGDES | L7: DeSoto
A8: DGWAR | B8: =Checklist!$B$1 -> 202511 | C8: GJ | D8: =D7 -> DC1104251 | E8: =D8 -> DC1104251 | F8: =Checklist!$A$6 -> 45965 | G8: 0 | H8: 4953.9 | I8: =$F$2 -> 45965 | J8: Checks Deposited - DG De Soto, Warren, Tremont and Effingham | K8: DGWAR-1950-0000-000- | L8: confirm State Street booked debit to 1950
A9: DGTRE | B9: =Checklist!$B$1 -> 202511 | C9: GJ | D9: =D8 -> DC1104251 | E9: =D9 -> DC1104251 | F9: =Checklist!$A$6 -> 45965 | G9: 0 | H9: 14531 | I9: =$F$2 -> 45965 | J9: Checks Deposited - DG De Soto, Warren, Tremont and Effingham | K9: DGTRE-1950-0000-000- | L9: confirm State Street booked debit to 1950
A10: LCREE | B10: =Checklist!$B$1 -> 202511 | C10: GJ | D10: =D9 -> DC1104251 | E10: =D10 -> DC1104251 | F10: =Checklist!$A$6 -> 45965 | G10: 0 | H10: 16917.97 | I10: =$F$2 -> 45965 | J10: Checks Deposited - DG De Soto, Warren, Tremont and Effingham | K10: LCREE-1950-0000-000- | L10: Effingham
A11: DGWAR | B11: =Checklist!$B$1 -> 202511 | C11: GJ | D11: =D10 -> DC1104251 | E11: =D11 -> DC1104251 | F11: =Checklist!$A$6 -> 45965 | G11: 4953.9 | H11: 0 | I11: =$F$2 -> 45965 | J11: Checks Deposited - DG De Soto, Warren, Tremont and Effingham | K11: DGWAR-1900-0000-000-LCREE
A12: DGTRE | B12: =Checklist!$B$1 -> 202511 | C12: GJ | D12: =D11 -> DC1104251 | E12: =D12 -> DC1104251 | F12: =Checklist!$A$6 -> 45965 | G12: 14531 | H12: 0 | I12: =$F$2 -> 45965 | J12: Checks Deposited - DG De Soto, Warren, Tremont and Effingham | K12: DGTRE-1900-0000-000-LCREE
A13: LCREE | B13: =Checklist!$B$1 -> 202511 | C13: GJ | D13: =D12 -> DC1104251 | E13: =D13 -> DC1104251 | F13: =Checklist!$A$6 -> 45965 | G13: 0 | H13: 4953.9 | I13: =$F$2 -> 45965 | J13: Checks Deposited - DG De Soto, Warren, Tremont and Effingham | K13: LCREE-1900-0000-000-DGWAR
A14: LCREE | B14: =Checklist!$B$1 -> 202511 | C14: GJ | D14: =D13 -> DC1104251 | E14: =D14 -> DC1104251 | F14: =Checklist!$A$6 -> 45965 | G14: 0 | H14: 14531 | I14: =$F$2 -> 45965 | J14: Checks Deposited - DG De Soto, Warren, Tremont and Effingham | K14: LCREE-1900-0000-000-DGTRE
A15: LCREE | B15: =Checklist!$B$1 -> 202511 | C15: GJ | D15: =D14 -> DC1104251 | E15: =D15 -> DC1104251 | F15: =Checklist!$A$6 -> 45965 | G15: 46666.67 | H15: 0 | I15: =$F$2 -> 45965 | J15: Rental Income - WGPON | K15: LCREE-1043-0000-000-
A16: LCREE | B16: =Checklist!$B$1 -> 202511 | C16: GJ | D16: =D15 -> DC1104251 | E16: =D16 -> DC1104251 | F16: =Checklist!$A$6 -> 45965 | G16: 0 | H16: 46666.67 | I16: =$F$2 -> 45965 | J16: Rental Income - WGPON | K16: LCREE-1470-0000-000-WFPON
A17: LCREF | B17: =Checklist!$B$1 -> 202511 | C17: GJ | D17: =D16 -> DC1104251 | E17: =D17 -> DC1104251 | F17: =Checklist!$A$6 -> 45965 | G17: 350000 | H17: 0 | I17: =$F$2 -> 45965 | J17: 519 Uptown Owner's Account Excess Funds | K17: LCREF-1065-0008-000-
A18: LCREF | B18: =Checklist!$B$1 -> 202511 | C18: GJ | D18: =D17 -> DC1104251 | E18: =D18 -> DC1104251 | F18: =Checklist!$A$6 -> 45965 | G18: 0 | H18: 350000 | I18: =$F$2 -> 45965 | J18: 519 Uptown Owner's Account Excess Funds | K18: LCREF-1470-0000-000-519UP
A19: TUERI | B19: =Checklist!$B$1 -> 202511 | C19: GJ | D19: =D18 -> DC1104251 | E19: =D19 -> DC1104251 | F19: =Checklist!$A$6 -> 45965 | G19: 1400000 | H19: 0 | I19: =$F$2 -> 45965 | J19: 15600 JFK Owner's Account Excess Funds | K19: TUERI-1065-0010-000-
A20: TUERI | B20: =Checklist!$B$1 -> 202511 | C20: GJ | D20: =D19 -> DC1104251 | E20: =D20 -> DC1104251 | F20: =Checklist!$A$6 -> 45965 | G20: 0 | H20: 1400000 | I20: =$F$2 -> 45965 | J20: 15600 JFK Owner's Account Excess Funds | K20: TUERI-1470-0000-000-15JFK
B21: =Checklist!$B$1 -> 202511 | C21: GJ | D21: =D20 -> DC1104251 | E21: =D21 -> DC1104251 | F21: =Checklist!$A$6 -> 45965 | I21: =$F$2 -> 45965
B22: =Checklist!$B$1 -> 202511 | C22: GJ | D22: =D21 -> DC1104251 | E22: =D22 -> DC1104251 | F22: =Checklist!$A$6 -> 45965 | I22: =$F$2 -> 45965
B23: =Checklist!$B$1 -> 202511 | C23: GJ | D23: =D22 -> DC1104251 | E23: =D23 -> DC1104251 | F23: =Checklist!$A$6 -> 45965 | I23: =$F$2 -> 45965
B24: =Checklist!$B$1 -> 202511 | C24: GJ | D24: =D23 -> DC1104251 | E24: =D24 -> DC1104251 | F24: =Checklist!$A$6 -> 45965 | I24: =$F$2 -> 45965
B25: =Checklist!$B$1 -> 202511 | C25: GJ | D25: =D24 -> DC1104251 | E25: =D25 -> DC1104251 | F25: =Checklist!$A$6 -> 45965 | I25: =$F$2 -> 45965
B26: =Checklist!$B$1 -> 202511 | C26: GJ | D26: =D25 -> DC1104251 | E26: =D26 -> DC1104251 | F26: =Checklist!$A$6 -> 45965 | I26: =$F$2 -> 45965
B27: =Checklist!$B$1 -> 202511 | C27: GJ | D27: =D26 -> DC1104251 | E27: =D27 -> DC1104251 | F27: =Checklist!$A$6 -> 45965 | I27: =$F$2 -> 45965
B28: =Checklist!$B$1 -> 202511 | C28: GJ | D28: =D27 -> DC1104251 | E28: =D28 -> DC1104251 | F28: =Checklist!$A$6 -> 45965 | I28: =$F$2 -> 45965

Sheet Cash Activity 11-5
A1: ="Daily Bank Activity - "&MONTH(Checklist!A7)&"/"&DAY(Checklist!A7)&"/"&YEAR(Checklist!A7) -> Daily Bank Activity - 11/5/2025
A2: Credit (+) / Debit (-)
B4: # | C4: Bank | D4: Acct Name | E4: Acct # | F4: Date | G4: Type | H4: Amount | I4: Bank Ref | J4: Bank Stmt Description | K4: Trans Type | L4: Entity | M4: AIT | N4: Short Description | O4: GL Account 1 | P4: GL Account 2 | Q4: Posted?
B5: 1 | C5: PNC | D5: LCFH REIT | E5: 8026459924 | F5: 45966 | G5: CR | H5: 437.79 | I5: '00000000000 | J5: PNC SWEEP INTEREST @ 0.000000 EFFECTIVE DATE 11-04 | K5: =IF(ISNUMBER(SEARCH("Manual Payment - ",N5,1)),"AP",IF(ISNUMBER(SEARCH("Payment - Concur",N5,1)),"WDL",IF(ISNUMBER(SEARCH("Payroll Transfer",N5,1)),"XFR",IF(ISNUMBER(SEARCH("XFR",N5,1)),"XFR",IF(H5>0,"RCT","WDL"))))) -> RCT | L5: =VLOOKUP(D5,'Entity Code'!A:B,2,0) -> LCFHR | N5: Overnight interest sweep PNC LCFHR account. No entry required | O5: N/A | P5: N/A | Q5: N/A
B6: 2 | C6: PNC | D6: LCFH REIT | E6: 8026459924 | F6: 45966 | G6: CR | H6: 5072833.3 | I6: '00000000000 | J6: SWEEP TRANSFR FROM INVESTMENT ACCT 8026459924 | K6: =IF(ISNUMBER(SEARCH("Manual Payment - ",N6,1)),"AP",IF(ISNUMBER(SEARCH("Payment - Concur",N6,1)),"WDL",IF(ISNUMBER(SEARCH("Payroll Transfer",N6,1)),"XFR",IF(ISNUMBER(SEARCH("XFR",N6,1)),"XFR",IF(H6>0,"RCT","WDL"))))) -> RCT | L6: =VLOOKUP(D6,'Entity Code'!A:B,2,0) -> LCFHR | N6: Overnight interest sweep PNC LCFHR account. No entry required | O6: N/A | P6: N/A | Q6: N/A
B7: 3 | C7: PNC | D7: LCFH REIT | E7: 8026459924 | F7: 45966 | G7: DR | H7: -50350317 | I7: '00000000000 | J7: SWEEP TO INVESTMENT ACCT# 8026459924 | K7: =IF(ISNUMBER(SEARCH("Manual Payment - ",N7,1)),"AP",IF(ISNUMBER(SEARCH("Payment - Concur",N7,1)),"WDL",IF(ISNUMBER(SEARCH("Payroll Transfer",N7,1)),"XFR",IF(ISNUMBER(SEARCH("XFR",N7,1)),"XFR",IF(H7>0,"RCT","WDL"))))) -> WDL | L7: =VLOOKUP(D7,'Entity Code'!A:B,2,0) -> LCFHR | N7: Overnight interest sweep PNC LCFHR account. No entry required | O7: N/A | P7: N/A | Q7: N/A
B8: 4 | C8: PNC | D8: LCREF | E8: 8026497285 | F8: 45966 | G8: DR | H8: -200000 | I8: 'PAB5E0054P8I46SR | J8: WIRE TRANSFER ISO AMT:USD 200000.00 STTLMT DATE:11 | K8: =IF(ISNUMBER(SEARCH("Manual Payment - ",N8,1)),"AP",IF(ISNUMBER(SEARCH("Payment - Concur",N8,1)),"WDL",IF(ISNUMBER(SEARCH("Payroll Transfer",N8,1)),"XFR",IF(ISNUMBER(SEARCH("XFR",N8,1)),"XFR",IF(H8>0,"RCT","WDL"))))) -> WDL | L8: =VLOOKUP(D8,'Entity Code'!A:B,2,0) -> LCREF | N8: 7th & Hill - Protective Advance #1 | O8: 2701-LMS0-000 | P8: N/A | Q8: SS&C to post
B9: 5 | C9: JPM | D9: LADDER CAPITAL FINANCE LLC OPERATIN | E9: 865357602 | F9: 45966 | G9: Debit | H9: -5769.23 | I9: 2572100309JO | J9: FEDWIRE DEBIT | K9: =IF(ISNUMBER(SEARCH("Manual Payment - ",N9,1)),"AP",IF(ISNUMBER(SEARCH("Payment - Concur",N9,1)),"WDL",IF(ISNUMBER(SEARCH("Payroll Transfer",N9,1)),"XFR",IF(ISNUMBER(SEARCH("XFR",N9,1)),"XFR",IF(H9>0,"RCT","WDL"))))) -> AP | L9: =VLOOKUP(D9,'Entity Code'!A:B,2,0) -> LCF | N9: Manual Payment - Item Six | O9: N/A | P9: N/A | Q9: Ladder to post
B10: 6 | C10: PNC | D10: LCF Payroll | E10: 8147891123 | F10: 45966 | G10: DR | H10: -88.15 | I10: '25B5C4439LA02WIZ | J10: WIRE TRANSFER ISO STTLMT DATE:11052025 CLR SYS REF | K10: =IF(ISNUMBER(SEARCH("Manual Payment - ",N10,1)),"AP",IF(ISNUMBER(SEARCH("Payment - Concur",N10,1)),"WDL",IF(ISNUMBER(SEARCH("Payroll Transfer",N10,1)),"XFR",IF(ISNUMBER(SEARCH("XFR",N10,1)),"XFR",IF(H10>0,"RCT","WDL"))))) -> WDL | L10: =VLOOKUP(D10,'Entity Code'!A:B,2,0) -> LCF | N10: Payroll - Trinet service fee | O10: LCF -1745-0000-000- | P10: N/A | Q10: Ladder to post
B11: 7 | C11: PNC | D11: LCFH REIT | E11: 8026459924 | F11: 45966 | G11: CR | H11: 2045.61 | I11: '25B5M3511CX10CP7 | J11: WIRE TRANSFER ISO AMT:USD 2045.61 STTLMT DATE:1105 | K11: =IF(ISNUMBER(SEARCH("Manual Payment - ",N11,1)),"AP",IF(ISNUMBER(SEARCH("Payment - Concur",N11,1)),"WDL",IF(ISNUMBER(SEARCH("Payroll Transfer",N11,1)),"XFR",IF(ISNUMBER(SEARCH("XFR",N11,1)),"XFR",IF(H11>0,"RCT","WDL"))))) -> RCT | L11: =VLOOKUP(D11,'Entity Code'!A:B,2,0) -> LCFHR | N11: JPM Securities Repo Margin Interest | O11: 2701-CAMR-000 | P11: N/A | Q11: SS&C to post
B12: 8 | C12: JPM | D12: LADDER CAPITAL FINANCE LLC TRADING | E12: 865357610 | F12: 45966 | G12: Credit | H12: 7500 | I12: 0734911309FF | J12: FEDWIRE CREDIT | K12: =IF(ISNUMBER(SEARCH("Manual Payment - ",N12,1)),"AP",IF(ISNUMBER(SEARCH("Payment - Concur",N12,1)),"WDL",IF(ISNUMBER(SEARCH("Payroll Transfer",N12,1)),"XFR",IF(ISNUMBER(SEARCH("XFR",N12,1)),"XFR",IF(H12>0,"RCT","WDL"))))) -> RCT | L12: =VLOOKUP(D12,'Entity Code'!A:B,2,0) -> LCF | N12: Consent Fee - Village At Westfork | O12: 2701-LMS0-000 | P12: N/A | Q12: SS&C to post
B13: 9 | C13: JPM | D13: LADDER CAPITAL CRE EQUITY LLC | E13: 528280121 | F13: 45966 | G13: Credit | H13: 29914.14 | I13: 0229941309FF | J13: FEDWIRE CREDIT | K13: =IF(ISNUMBER(SEARCH("Manual Payment - ",N13,1)),"AP",IF(ISNUMBER(SEARCH("Payment - Concur",N13,1)),"WDL",IF(ISNUMBER(SEARCH("Payroll Transfer",N13,1)),"XFR",IF(ISNUMBER(SEARCH("XFR",N13,1)),"XFR",IF(H13>0,"RCT","WDL"))))) -> RCT | L13: =VLOOKUP(D13,'Entity Code'!A:B,2,0) -> LCREE | N13: Excess Funds - DGPEO | O13: LCREE-1470-0000-000-DGPEO | P13: N/A | Q13: Ladder to post
B14: 10 | C14: PNC | D14: LCREF | E14: 8026497285 | F14: 45966 | G14: CR | H14: 44016841 | I14: '25B5L49219513YBK | J14: WIRE TRANSFER ISO AMT:USD 44016841.00 STTLMT DATE: | K14: =IF(ISNUMBER(SEARCH("Manual Payment - ",N14,1)),"AP",IF(ISNUMBER(SEARCH("Payment - Concur",N14,1)),"WDL",IF(ISNUMBER(SEARCH("Payroll Transfer",N14,1)),"XFR",IF(ISNUMBER(SEARCH("XFR",N14,1)),"XFR",IF(H14>0,"RCT","WDL"))))) -> RCT | L14: =VLOOKUP(D14,'Entity Code'!A:B,2,0) -> LCREF | N14: 17 West 60th Street Payoff Proceeds | O14: 2701-LMS0-000 | P14: N/A | Q14: SS&C to post
B15: 11 | C15: PNC | D15: LCREF | E15: 8026497285 | F15: 45966 | G15: CR | H15: 300000 | I15: '25B5F54446A15W7C | J15: WIRE TRANSFER ISO AMT:USD 300000.00 STTLMT DATE:11 | K15: =IF(ISNUMBER(SEARCH("Manual Payment - ",N15,1)),"AP",IF(ISNUMBER(SEARCH("Payment - Concur",N15,1)),"WDL",IF(ISNUMBER(SEARCH("Payroll Transfer",N15,1)),"XFR",IF(ISNUMBER(SEARCH("XFR",N15,1)),"XFR",IF(H15>0,"RCT","WDL"))))) -> XFR | L15: =VLOOKUP(D15,'Entity Code'!A:B,2,0) -> LCREF | N15: XFR from LCFP4 to LCREF | O15: 2701-CAMR-000 | P15: N/A | Q15: SS&C to post
B16: 12 | C16: PNC | D16: LADDER CRE PARENT | E16: 8026497277 | F16: 45966 | G16: CR | H16: 44500000 | I16: '25B5L5858NO06D8M | J16: BOOK TRANSFER CREDIT 006D8M ORIGINATOR:LADDER CRE | K16: =IF(ISNUMBER(SEARCH("Manual Payment - ",N16,1)),"AP",IF(ISNUMBER(SEARCH("Payment - Concur",N16,1)),"WDL",IF(ISNUMBER(SEARCH("Payroll Transfer",N16,1)),"XFR",IF(ISNUMBER(SEARCH("XFR",N16,1)),"XFR",IF(H16>0,"RCT","WDL"))))) -> RCT | L16: =VLOOKUP(D16,'Entity Code'!A:B,2,0) -> LCREP | N16: Dividend Payment | O16: LCREP-1470-0000-000-LCREF | P16: N/A | Q16: Ladder to post
B17: 12 | C17: PNC | D17: LCREF | E17: 8026497285 | F17: 45966 | G17: DR | H17: -44500000 | I17: '25B5L5858NO06D8M | J17: BOOK TRANSFER DEBIT 006D8M ORIGINATOR:LADDER CRE F | K17: =IF(ISNUMBER(SEARCH("Manual Payment - ",N17,1)),"AP",IF(ISNUMBER(SEARCH("Payment - Concur",N17,1)),"WDL",IF(ISNUMBER(SEARCH("Payroll Transfer",N17,1)),"XFR",IF(ISNUMBER(SEARCH("XFR",N17,1)),"XFR",IF(H17>0,"RCT","WDL"))))) -> WDL | L17: =VLOOKUP(D17,'Entity Code'!A:B,2,0) -> LCREF | N17: Dividend Payment | O17: LCREF-3670-0000-000-LCREP | P17: N/A | Q17: Ladder to post
B18: 13 | C18: PNC | D18: LCFH REIT | E18: 8026459924 | F18: 45966 | G18: CR | H18: 44055000 | I18: '25B5L5858OB1421K | J18: BOOK TRANSFER CREDIT 00421K ORIGINATOR:LADDER CRE | K18: =IF(ISNUMBER(SEARCH("Manual Payment - ",N18,1)),"AP",IF(ISNUMBER(SEARCH("Payment - Concur",N18,1)),"WDL",IF(ISNUMBER(SEARCH("Payroll Transfer",N18,1)),"XFR",IF(ISNUMBER(SEARCH("XFR",N18,1)),"XFR",IF(H18>0,"RCT","WDL"))))) -> RCT | L18: =VLOOKUP(D18,'Entity Code'!A:B,2,0) -> LCFHR | N18: Partnership Distribution | O18: MID2R-1470-0000-000-LCREP | P18: N/A | Q18: Ladder to post
B19: 13 | C19: PNC | D19: LADDER CRE PARENT | E19: 8026497277 | F19: 45966 | G19: DR | H19: -44055000 | I19: '25B5L5858OB1421K | J19: BOOK TRANSFER DEBIT 00421K ORIGINATOR:LADDER CRE P | K19: =IF(ISNUMBER(SEARCH("Manual Payment - ",N19,1)),"AP",IF(ISNUMBER(SEARCH("Payment - Concur",N19,1)),"WDL",IF(ISNUMBER(SEARCH("Payroll Transfer",N19,1)),"XFR",IF(ISNUMBER(SEARCH("XFR",N19,1)),"XFR",IF(H19>0,"RCT","WDL"))))) -> WDL | L19: =VLOOKUP(D19,'Entity Code'!A:B,2,0) -> LCREP | N19: Partnership Distribution | O19: LCREP-3670-0000-000-MID2R | P19: N/A | Q19: Ladder to post
B20: 14 | C20: PNC | D20: Ladder Capital Finance | E20: 8026459916 | F20: 45966 | G20: CR | H20: 445000 | I20: '25B5L585905Z5CB9 | J20: BOOK TRANSFER CREDIT 005CB9 ORIGINATOR:LADDER CRE | K20: =IF(ISNUMBER(SEARCH("Manual Payment - ",N20,1)),"AP",IF(ISNUMBER(SEARCH("Payment - Concur",N20,1)),"WDL",IF(ISNUMBER(SEARCH("Payroll Transfer",N20,1)),"XFR",IF(ISNUMBER(SEARCH("XFR",N20,1)),"XFR",IF(H20>0,"RCT","WDL"))))) -> RCT | L20: =VLOOKUP(D20,'Entity Code'!A:B,2,0) -> LCF | N20: Partnership Distribution | O20: LMID2-1470-0000-000-LCREP | P20: N/A | Q20: Ladder to post
B21: 14 | C21: PNC | D21: LADDER CRE PARENT | E21: 8026497277 | F21: 45966 | G21: DR | H21: -445000 | I21: '25B5L585905Z5CB9 | J21: BOOK TRANSFER DEBIT 005CB9 ORIGINATOR:LADDER CRE P | K21: =IF(ISNUMBER(SEARCH("Manual Payment - ",N21,1)),"AP",IF(ISNUMBER(SEARCH("Payment - Concur",N21,1)),"WDL",IF(ISNUMBER(SEARCH("Payroll Transfer",N21,1)),"XFR",IF(ISNUMBER(SEARCH("XFR",N21,1)),"XFR",IF(H21>0,"RCT","WDL"))))) -> WDL | L21: =VLOOKUP(D21,'Entity Code'!A:B,2,0) -> LCREP | N21: Partnership Distribution | O21: LCREP-3670-0000-000-LMID2 | P21: N/A | Q21: Ladder to post
B22: 15 | C22: PNC | D22: LCI | E22: 8026496012 | F22: 45966 | G22: CR | H22: 1220000 | I22: '25B5L00186410RP4 | J22: BOOK TRANSFER CREDIT 000RP4 ORIGINATOR:TUEBOR REIT | K22: =IF(ISNUMBER(SEARCH("Manual Payment - ",N22,1)),"AP",IF(ISNUMBER(SEARCH("Payment - Concur",N22,1)),"WDL",IF(ISNUMBER(SEARCH("Payroll Transfer",N22,1)),"XFR",IF(ISNUMBER(SEARCH("XFR",N22,1)),"XFR",IF(H22>0,"RCT","WDL"))))) -> RCT | L22: =VLOOKUP(D22,'Entity Code'!A:B,2,0) -> LCI | N22: Capital Distribution | O22: 3800-0000-000 | P22: N/A | Q22: SS&C to post
B23: 15 | C23: PNC | D23: Tuebor REIT | E23: 8026495976 | F23: 45966 | G23: DR | H23: -1220000 | I23: '25B5L00186410RP4 | J23: BOOK TRANSFER DEBIT 000RP4 ORIGINATOR:TUEBOR REIT | K23: =IF(ISNUMBER(SEARCH("Manual Payment - ",N23,1)),"AP",IF(ISNUMBER(SEARCH("Payment - Concur",N23,1)),"WDL",IF(ISNUMBER(SEARCH("Payroll Transfer",N23,1)),"XFR",IF(ISNUMBER(SEARCH("XFR",N23,1)),"XFR",IF(H23>0,"RCT","WDL"))))) -> WDL | L23: =VLOOKUP(D23,'Entity Code'!A:B,2,0) -> TUERI | N23: Capital Distribution | O23: 1450-0000-000 | P23: N/A | Q23: SS&C to post
B24: 16 | C24: PNC | D24: LCFH REIT | E24: 8026459924 | F24: 45966 | G24: CR | H24: 1220000 | I24: '25B5L00186MZ4IZM | J24: BOOK TRANSFER CREDIT 004IZM ORIGINATOR:LADDER CAPI | K24: =IF(ISNUMBER(SEARCH("Manual Payment - ",N24,1)),"AP",IF(ISNUMBER(SEARCH("Payment - Concur",N24,1)),"WDL",IF(ISNUMBER(SEARCH("Payroll Transfer",N24,1)),"XFR",IF(ISNUMBER(SEARCH("XFR",N24,1)),"XFR",IF(H24>0,"RCT","WDL"))))) -> XFR | L24: =VLOOKUP(D24,'Entity Code'!A:B,2,0) -> LCFHR | N24: XFR from LCI PNC to LCFHR PNC | O24: 2701-CAMR-000 | P24: N/A | Q24: SS&C to post
B25: 16 | C25: PNC | D25: LCI | E25: 8026496012 | F25: 45966 | G25: DR | H25: -1220000 | I25: '25B5L00186MZ4IZM | J25: BOOK TRANSFER DEBIT 004IZM ORIGINATOR:LADDER CAPIT | K25: =IF(ISNUMBER(SEARCH("Manual Payment - ",N25,1)),"AP",IF(ISNUMBER(SEARCH("Payment - Concur",N25,1)),"WDL",IF(ISNUMBER(SEARCH("Payroll Transfer",N25,1)),"XFR",IF(ISNUMBER(SEARCH("XFR",N25,1)),"XFR",IF(H25>0,"RCT","WDL"))))) -> XFR | L25: =VLOOKUP(D25,'Entity Code'!A:B,2,0) -> LCI | N25: XFR from LCI PNC to LCFHR PNC | O25: 2701-CAMR-000 | P25: N/A | Q25: SS&C to post
B26: 17 | C26: JPM | D26: LADDER CAPITAL FINANCE LLC OPERATIN | E26: 865357602 | F26: 45966 | G26: Debit | H26: -38475.5 | I26: 8398500309JO | J26: FEDWIRE DEBIT | K26: =IF(ISNUMBER(SEARCH("Manual Payment - ",N26,1)),"AP",IF(ISNUMBER(SEARCH("Payment - Concur",N26,1)),"WDL",IF(ISNUMBER(SEARCH("Payroll Transfer",N26,1)),"XFR",IF(ISNUMBER(SEARCH("XFR",N26,1)),"XFR",IF(H26>0,"RCT","WDL"))))) -> AP | L26: =VLOOKUP(D26,'Entity Code'!A:B,2,0) -> LCF | N26: Manual Payment - Default Resolution Network | O26: N/A | P26: N/A | Q26: Ladder to post

Sheet Cash Entries 11-5
A1: ENTITY | B1: YEARMONTH | C1: SOURCE | D1: BATCH ID | E1: BATCH DESCRIPTION | F1: BATCHDATE | G1: DR_AMT | H1: CR AMT | I1: TRXDATE | J1: DIST REFERENCE | K1: GPACCT
A2: LCF | B2: =Checklist!$B$1 -> 202511 | C2: GJ | D2: =Checklist!$B$7 -> DC1105251 | E2: =D2 -> DC1105251 | F2: =Checklist!$A$7 -> 45966 | G2: 88.15 | H2: 0 | I2: =$F$2 -> 45966 | J2: Payroll - Trinet service fee | K2: LCF -1745-0000-000-
A3: LCF | B3: =Checklist!$B$1 -> 202511 | C3: GJ | D3: =D2 -> DC1105251 | E3: =D3 -> DC1105251 | F3: =$F$2 -> 45966 | G3: 0 | H3: 88.15 | I3: =$F$2 -> 45966 | J3: Payroll - Trinet service fee | K3: LCF -1006-0000-000-
A4: LCREE | B4: =Checklist!$B$1 -> 202511 | C4: GJ | D4: DC1105252 | E4: =D4 -> DC1105252 | F4: =$F$2 -> 45966 | G4: 29914.14 | H4: 0 | I4: =$F$2 -> 45966 | J4: Excess Funds - DGPEO | K4: LCREE-1043-0000-000-
A5: LCREE | B5: =Checklist!$B$1 -> 202511 | C5: GJ | D5: =D4 -> DC1105252 | E5: =D5 -> DC1105252 | F5: =$F$2 -> 45966 | G5: 0 | H5: 29914.14 | I5: =$F$2 -> 45966 | J5: Excess Funds - DGPEO | K5: LCREE-1470-0000-000-DGPEO
B6: =Checklist!$B$1 -> 202511 | C6: GJ | D6: DC1105253 | E6: =D6 -> DC1105253 | F6: =$F$2 -> 45966 | I6: =$F$2 -> 45966
B7: =Checklist!$B$1 -> 202511 | C7: GJ | D7: =D6 -> DC1105253 | E7: =D7 -> DC1105253 | F7: =$F$2 -> 45966 | I7: =$F$2 -> 45966
B8: =Checklist!$B$1 -> 202511 | C8: GJ | D8: =D7 -> DC1105253 | E8: =D8 -> DC1105253 | F8: =$F$2 -> 45966 | I8: =$F$2 -> 45966
B9: =Checklist!$B$1 -> 202511 | C9: GJ | D9: =D8 -> DC1105253 | E9: =D9 -> DC1105253 | F9: =$F$2 -> 45966 | I9: =$F$2 -> 45966
B10: =Checklist!$B$1 -> 202511 | C10: GJ | D10: =D9 -> DC1105253 | E10: =D10 -> DC1105253 | F10: =$F$2 -> 45966 | I10: =$F$2 -> 45966
B11: =Checklist!$B$1 -> 202511 | C11: GJ | D11: =D10 -> DC1105253 | E11: =D11 -> DC1105253 | F11: =$F$2 -> 45966 | I11: =$F$2 -> 45966
B12: =Checklist!$B$1 -> 202511 | C12: GJ | D12: =D11 -> DC1105253 | E12: =D12 -> DC1105253 | F12: =$F$2 -> 45966 | I12: =$F$2 -> 45966
B13: =Checklist!$B$1 -> 202511 | C13: GJ | D13: =D12 -> DC1105253 | E13: =D13 -> DC1105253 | F13: =$F$2 -> 45966 | I13: =$F$2 -> 45966
B14: =Checklist!$B$1 -> 202511 | C14: GJ | D14: =D13 -> DC1105253 | E14: =D14 -> DC1105253 | F14: =$F$2 -> 45966 | I14: =$F$2 -> 45966
B15: =Checklist!$B$1 -> 202511 | C15: GJ | D15: =D14 -> DC1105253 | E15: =D15 -> DC1105253 | F15: =$F$2 -> 45966 | I15: =$F$2 -> 45966
B16: =Checklist!$B$1 -> 202511 | C16: GJ | D16: =D15 -> DC1105253 | E16: =D16 -> DC1105253 | F16: =$F$2 -> 45966 | I16: =$F$2 -> 45966
B17: =Checklist!$B$1 -> 202511 | C17: GJ | D17: =D16 -> DC1105253 | E17: =D17 -> DC1105253 | F17: =$F$2 -> 45966 | I17: =$F$2 -> 45966
B18: =Checklist!$B$1 -> 202511 | C18: GJ | D18: =D17 -> DC1105253 | E18: =D18 -> DC1105253 | F18: =$F$2 -> 45966 | I18: =$F$2 -> 45966
... B25: =Checklist!$B$1 -> 202511 | C25: GJ | D25: =D24 -> DC1105253 | E25: =D25 -> DC1105253 | F25: =$F$2 -> 45966 | I25: =$F$2 -> 45966

Sheet Cash Activity 11-6
A1: ="Daily Bank Activity - "&MONTH(Checklist!A8)&"/"&DAY(Checklist!A8)&"/"&YEAR(Checklist!A8) -> Daily Bank Activity - 11/6/2025
A2: Credit (+) / Debit (-)
